Workbook

Sheet Cover
B2: TWB — Global Secure Destruction & Demilitarization Platform
B3: 10-15 Year Revenue Forecast & Market Sizing Model | Board / Investor Working Model | August 2026
B6: How this model is built
B8: This model separates two kinds of numbers throughout, colour-coded so nothing gets mistaken for the other:
B9: SOURCED market data
B10: Pulled from published market research, government and NGO reporting (Landmine Monitor, World Bank / Ukraine RDNA4, EOD market research houses, scrap metal indices). Black or green text. Full citations on the Sources tab.
B12: MODELED assumptions — yellow fill, blue font
B13: TWB-specific judgment calls: market share capture, margin, capex phasing, entry timing. These are the levers for the board conversation and are meant to be flexed together with the board — they are estimates, not market facts.
B15: Tabs in this workbook
B16: TAM-SAM-SOM
B17: Global addressable market build-up across all destruction sub-segments (2026 baseline), and TWB's serviceable/obtainable slice
B18: Segment Detail
... B36: This is fundamentally a share-capture and execution-risk story, not a market-size-risk story: the addressable spend already exists and is documented across multiple independent sources. The open question this model is built to stress-test is TWB's ability to win and deliver against it — hence the Scenarios tab.

Sheet TAM-SAM-SOM
B2: Global Addressable Market — TAM / SAM / SOM
B3: 2026 baseline, USD millions unless noted. See Segment Detail tab for full build of each line.
B6: STEP 1 — TAM: Total global spend across all secure destruction / demilitarization sub-segments
B7: Segment | C7: 2026 value ($M) | D7: Annual growth (modeled) | E7: Source basis | F7: Note
B8: Humanitarian mine action (global donor + national funding) | C8: 1070 | D8: 0.01 | E8: SOURCED | F8: Landmine Monitor 2025 — global 2024 funding total. Growth held near-flat (1%/yr): funding actually fell 5% in 2024 vs 2023, and US foreign-assistance freezes are an active headwind — modeled as roughly keeping pace with inflation only, not real growth.
B9: Military/law-enforcement EOD equipment & services (global) | C9: 9000 | D9: 0.045 | E9: SOURCED (mid-point) | F9: Market research houses range $8.5-9.6bn for 2025 with reported CAGRs clustering around 3-5%; 4.5% used as the blended mid-point.
B10: Ammunition demilitarization / stockpile destruction (global, modeled) | C10: 2500 | D10: 0.07 | E10: MODELED | F10: Not separately reported by market researchers — sized at ~3% of global ammunition production spend. Growth rate follows the ammunition production market itself, which multiple sources put at a wide 4-14% CAGR range given current rearmament cycles; 7% used as a conservative-of-midpoint estimate.
B11: Chemical weapons demilitarization (residual global programs) | C11: 400 | D11: -0.03 | E11: MODELED | F11: Legacy CW stockpile destruction (OPCW-related, Syria/Libya/Russia residual programs) — this is a SHRINKING segment as legacy programs complete; modeled at -3%/yr decline.
B12: Ukraine-specific landmine/UXO clearance (incremental, not in above) | C12: 2000 | D12: 0.06 | E12: MODELED (phased draw-down of $29-31bn total need) | F12: Total programme need is $29-31bn; this line estimates realistic ANNUAL disbursement, which is expected to ramp up sharply as reconstruction financing scales post-conflict, then taper as the total need gets worked down over ~15-20 years. A single 6%/yr compound rate is a deliberately CONSERVATIVE simplification of what is really a ramp-then-taper curve (which could see high-teens growth in years 3-8 followed by deceleration) — using a lower flat rate avoids overstating the later years, since a realistic curve's average is well below its peak-year growth. See note below the table.
B13: TOTAL TAM (annual global spend, 2026) | C13: =SUM(C8:C12) -> 14970
B14: Blended TAM growth rate (revenue-weighted, 2026) | C14: =SUMPRODUCT(C8:C12,D8:D12)/C13 -> 0.046673347
B15: Note on Ukraine growth simplification: the real shape of Ukraine disbursement is a ramp-up (as reconstruction financing scales through years 3-8) followed by a taper (as the $29-31bn total need gets progressively worked down and easy sites are exhausted) — a single compound growth rate cannot capture that curve exactly. 6%/yr is set conservatively low precisely because compounding for 15 straight years at a higher rate (even the historically-plausible mid-teens seen in recent years) would overstate the total by Year 15 far more than it understates the middle years. Flagged here rather than hidden; the Revenue Build tab's own Ukraine ramp (which the board should treat as primary for TWB's OWN revenue) already models a ramp-then-decelerate shape directly rather than relying on this simplified TAM growth line — this line only affects the size of the market TWB is chasing, not TWB's own revenue path.
B17: STEP 2 — SAM: Serviceable market TWB can realistically address given its model
B18: Adjustments applied to TAM to reach the market TWB's business model can actually serve:
B20: Adjustment | C20: Factor | D20: Rationale
B21: Chemical weapons demil — included, but heavily discounted for market access reality | C21: 0.15 | D21: MODELED: unlike the other segments, this market is almost entirely government-to-government, OPCW-licensed, and concentrated among a handful of state-sponsored or state-owned incumbents. A 15% access factor reflects that TWB can realistically pursue a thin slice of this spend (specialist subcontracts, niche capability gaps) rather than compete for it broadly — see Segment Detail tab.
B22: Geographic reach discount (TWB realistically active in Canada/US/EU/Ukraine/select ME, not full global TAM) | C22: 0.55 | D22: Modeled: reflects export control, licensing, and relationship-building realities of operating in this sector — most players are regional/national even at scale
B23: Service-line fit discount (TWB's model — secure destruction + metals recovery — fits a subset of each segment's total spend, e.g., excludes pure EOD equipment manufacturing, R&D, and training-only contracts) | C23: 0.65 | D23: Modeled: TWB competes for destruction/disposal SERVICES specifically, not equipment sales, software, or standalone training contracts which make up a meaningful share of reported market sizes
B25: SAM calculation (2026 baseline):
B26: TAM, all segments (incl. chemical weapons) | C26: =C8+C9+C10+C11+C12 -> 14970
B27: x Chemical weapons access factor (applied only to that $400M slice — see note below) | C27: =C21 -> 0.15
B28: x Geographic reach factor | C28: =C22 -> 0.55
B29: x Service-line fit factor | C29: =C23 -> 0.65
B30: SAM (serviceable addressable market, 2026) | C30: =(C8+C9+C10+C12)*C22*C23+C11*C21*C22*C23 -> 5230.225
B31: (Chemical weapons contributes its $400M TAM x 15% access x 55% geo x 65% service-fit = a small, explicit slice — shown separately since its access economics differ fundamentally from every other segment, not because it's excluded.)
B33: STEP 2b — SAM GROWS: 16-year projection applying each segment's own growth rate
B34: This is the number the Revenue Build and Headcount tabs actually compare TWB's revenue against — NOT the static 2026 figure above. Each segment compounds at the growth rate set in the Step 1 table (column D). The Geographic reach and Service-line fit discount factors are held constant (a simplifying assumption — TWB's addressable slice of each market is assumed proportionally stable, not itself growing or shrinking as a share of the segment).
B35: Calendar year | H35: 2026 | I35: 2027 | J35: 2028 | K35: 2029 | L35: 2030 | M35: 2031 | N35: 2032 | O35: 2033 | P35: 2034 | Q35: 2035 | R35: 2036 | S35: 2037 | T35: 2038 | U35: 2039 | V35: 2040 | W35: 2041
B36: Model year | H36: Y0 | I36: Y1 | J36: Y2 | K36: Y3 | L36: Y4 | M36: Y5 | N36: Y6 | O36: Y7 | P36: Y8 | Q36: Y9 | R36: Y10 | S36: Y11 | T36: Y12 | U36: Y13 | V36: Y14 | W36: Y15
B37: Mine action | H37: =C8 -> 1070 | I37: =H37*(1+$D$8) -> 1080.7 | J37: =I37*(1+$D$8) -> 1091.507 | K37: =J37*(1+$D$8) -> 1102.4221 | L37: =K37*(1+$D$8) -> 1113.4463 | M37: =L37*(1+$D$8) -> 1124.5808 | N37: =M37*(1+$D$8) -> 1135.8266 | O37: =N37*(1+$D$8) -> 1147.1848 | P37: =O37*(1+$D$8) -> 1158.6567 | ... W37: =V37*(1+$D$8) -> 1242.2368
B38: EOD equip.+svcs | H38: =C9 -> 9000 | I38: =H38*(1+$D$9) -> 9405 | J38: =I38*(1+$D$9) -> 9828.225 | K38: =J38*(1+$D$9) -> 10270.495 | L38: =K38*(1+$D$9) -> 10732.667 | M38: =L38*(1+$D$9) -> 11215.637 | N38: =M38*(1+$D$9) -> 11720.341 | O38: =N38*(1+$D$9) -> 12247.756 | P38: =O38*(1+$D$9) -> 12798.906 | ... W38: =V38*(1+$D$9) -> 17417.542
B39: Ammo demil | H39: =C10 -> 2500 | I39: =H39*(1+$D$10) -> 2675 | J39: =I39*(1+$D$10) -> 2862.25 | K39: =J39*(1+$D$10) -> 3062.6075 | L39: =K39*(1+$D$10) -> 3276.99 | M39: =L39*(1+$D$10) -> 3506.3793 | N39: =M39*(1+$D$10) -> 3751.8259 | O39: =N39*(1+$D$10) -> 4014.4537 | P39: =O39*(1+$D$10) -> 4295.4654 | ... W39: =V39*(1+$D$10) -> 6897.5789
B40: Chem weapons | H40: =C11 -> 400 | I40: =H40*(1+$D$11) -> 388 | J40: =I40*(1+$D$11) -> 376.36 | K40: =J40*(1+$D$11) -> 365.0692 | L40: =K40*(1+$D$11) -> 354.11712 | M40: =L40*(1+$D$11) -> 343.49361 | N40: =M40*(1+$D$11) -> 333.1888 | O40: =N40*(1+$D$11) -> 323.19314 | P40: =O40*(1+$D$11) -> 313.49734 | ... W40: =V40*(1+$D$11) -> 253.30048
B41: Ukraine (incremental) | H41: =C12 -> 2000 | I41: =H41*(1+$D$12) -> 2120 | J41: =I41*(1+$D$12) -> 2247.2 | K41: =J41*(1+$D$12) -> 2382.032 | L41: =K41*(1+$D$12) -> 2524.9539 | M41: =L41*(1+$D$12) -> 2676.4512 | N41: =M41*(1+$D$12) -> 2837.0382 | O41: =N41*(1+$D$12) -> 3007.2605 | P41: =O41*(1+$D$12) -> 3187.6961 | ... W41: =V41*(1+$D$12) -> 4793.1164
B42: TAM, all segments (grown) | H42: =SUM(H37:H41) -> 14970 | I42: =SUM(I37:I41) -> 15668.7 | J42: =SUM(J37:J41) -> 16405.542 | K42: =SUM(K37:K41) -> 17182.626 | L42: =SUM(L37:L41) -> 18002.175 | M42: =SUM(M37:M41) -> 18866.542 | N42: =SUM(N37:N41) -> 19778.221 | O42: =SUM(O37:O41) -> 20739.849 | ... W42: =SUM(W37:W41) -> 30603.774
B44: SAM (grown, applying the same access/geo/service-fit factors each year) | H44: =(H37+H38+H39+H41)*$C$22*$C$23+H40*$C$21*$C$22*$C$23 -> 5230.225 | I44: =(I37+I38+I39+I41)*$C$22*$C$23+I40*$C$21*$C$22*$C$23 -> 5483.6568 | J44: =(J37+J38+J39+J41)*$C$22*$C$23+J40*$C$21*$C$22*$C$23 -> 5750.6149 | K44: =(K37+K38+K39+K41)*$C$22*$C$23+K40*$C$21*$C$22*$C$23 -> 6031.8534 | L44: =(L37+L38+L39+L41)*$C$22*$C$23+L40*$C$21*$C$22*$C$23 -> 6328.1701 | M44: =(M37+M38+M39+M41)*$C$22*$C$23+M40*$C$21*$C$22*$C$23 -> 6640.4097 | N44: =(N37+N38+N39+N41)*$C$22*$C$23+N40*$C$21*$C$22*$C$23 -> 6969.4661 | O44: =(O37+O38+O39+O41)*$C$22*$C$23+O40*$C$21*$C$22*$C$23 -> 7316.2856 | ... W44: =(W37+W38+W39+W41)*$C$22*$C$23+W40*$C$21*$C$22*$C$23 -> 10863.878
B45: SAM growth vs 2026 baseline | H45: =H44/H44-1 -> 0 | I45: =I44/H44-1 -> 0.048455229 | J45: =J44/H44-1 -> 0.099496651 | K45: =K44/H44-1 -> 0.15326843 | L45: =L44/H44-1 -> 0.20992312 | M45: =M44/H44-1 -> 0.2696222 | N45: =N44/H44-1 -> 0.33253658 | O45: =O44/H44-1 -> 0.3988472 | P45: =P44/H44-1 -> 0.46874562 | Q45: =Q44/H44-1 -> 0.54243468 | R45: =R44/H44-1 -> 0.62012917 | S45: =S44/H44-1 -> 0.70205657 | T45: =T44/H44-1 -> 0.78845784 | U45: =U44/H44-1 -> 0.8795882 | V45: =V44/H44-1 -> 0.97571806 | W45: =W44/H44-1 -> 1.0771339
B47: STEP 3 — SOM: Serviceable Obtainable Market (Year 15 target share of the GROWN Year-15 SAM)
B48: Target Year-15 share of SAM (modeled — see Scenarios tab for range) | C48: 0.1
B49: Year-15 SAM (grown — this is the correct denominator, not the static 2026 figure) | C49: =W44 -> 10863.878
...

Sheet Segment Detail
B2: Segment-by-Segment Market Detail
B3: Full sourcing and logic behind each TAM line
B6: 1. Humanitarian Mine Action
B7: Global humanitarian mine action (clearance, risk education, victim assistance)
B8: Size | C8: Global funding totaled $1.07 billion in 2024 — the second time annual mine action funding has surpassed $1 billion, a 4% increase from $1.03 billion in 2023. International donors provided $761 million; 26 affected states contributed a further $306.3 million to their own national programs (Landmine Monitor 2025).
B9: Donor concentration | C9: US, Germany, and the EU are the three largest donors. The five largest donors provided 62% ($468.8M) of international funding. This is a DONOR-FUNDED market, not a pure commercial market — contracts are typically won via competitive tender from governments, UN agencies (UNMAS), or NGOs (HALO Trust, MAG, GICHD) who hold the primary funding.
B10: Risk flag | C10: The US froze foreign assistance in Q1 2025, leading to termination of several humanitarian mine action programs, and international funding was already down 5% in 2024 vs 2023. This is a real headwind on the humanitarian side specifically — it is the reason the Ukraine-specific line below is modeled separately and conservatively.
B12: 2. Military / Law Enforcement EOD Equipment & Services
B13: Global commercial EOD market — equipment + services, defense and law enforcement end users
B14: Size (range across sources) | C14: Estimates vary materially by scope: equipment-only ranges $6.2-7.2bn (2025); equipment+services combined ranges $8.55-9.6bn (2025); one outlier source shows $5.69bn for equipment services only. This model uses a $9.0bn midpoint for the combined equipment+services TAM line.
B15: Segment mix | C15: Roughly 38% defense-driven procurement, ~34% law enforcement/counter-IED, ~28% robotics and remote-handling systems, per Global Growth Insights. EOD Robots segment alone is estimated at $2.75bn (2025), growing ~6.2% CAGR.
B16: Relevance to TWB | C16: This segment is the closest analog to TWB's existing small-arms/ordnance capability, and the most credible near-term expansion market: it already includes both military and police/law-enforcement end users, matching the stated domestic-to-military expansion path.
B18: 3. Ammunition Demilitarization / Stockpile Destruction
B19: Large-format ammunition, ordnance, and stockpile destruction — MODELED, not separately market-sized by researchers
B20: Why modeled | C20: No market research house publishes a clean 'ammunition demilitarization market size' figure — it is usually bundled inside broader defense sustainment or EOD numbers, or handled via bespoke government contracts and framework agreements (e.g., NATO Partnership for Peace Trust Fund projects, US Conventional Ammunition Demilitarization program, European national stockpile rationalization following NATO-standard re-equipment).
B21: Sizing logic | C21: The global ammunition PRODUCTION market is estimated in the $25-90bn range across sources (wide variance by scope/methodology) — for context only, not used directly. Demil/disposal spend is a much smaller downstream tail of this. This model estimates it at roughly $2.5bn/year globally, built up from known individual program scale: NATO PfP Trust Fund projects have run in the tens of millions per country over multi-year programs; single-country stockpile disposal programs (e.g., legacy Warsaw Pact ammunition destruction in Eastern Europe) have historically run $10-50M per multi-year program. Aggregated across ~30-40 active/latent national programs globally, ~$2-3bn/year is a reasonable order-of-magnitude.
B22: Board flag | C22: This is the single largest 'trust me' number in the model, since no clean third-party market report exists. Recommend commissioning bespoke primary research (e.g., interviews with NATO Support and Procurement Agency, national MoD disposal units) before using this figure in external investor materials without caveat.
B24: 4. Chemical Weapons Demilitarization
B25: Legacy CW stockpile destruction — now included as a phased, specialist revenue line (Year 10+)
B26: Size | C26: Modeled at ~$400M/year residual global spend — legacy programs (Syria, Libya, historical Russia/US stockpile destruction under CWC) are winding down or already complete; this is a shrinking, heavily government-controlled, specialist segment with very few commercial entrants and steep regulatory/licensing barriers (OPCW oversight).
B27: Market access | C27: Included in SAM at a 15% access factor (vs 55-65% for other segments) — reflecting that this market is structurally different: almost entirely government-to-government, tightly licensed under the Chemical Weapons Convention, and concentrated among a small number of state-sponsored or state-owned incumbents (e.g., national CW demil authorities, a handful of specialist contractors with existing OPCW certification).
B28: Entry path | C28: Modeled as TWB's latest and smallest phase of expansion (Year 10), entered only after the core EOD/mine action/ammunition demil business is established across Canada, the US, Europe, and Ukraine — realistically via a specific licensed capability, joint venture with an existing certified operator, or acquisition, not organic bid-and-win. Growth is modeled at a below-market 8%/year given the underlying global CW stockpile-destruction need is itself declining as legacy programs complete.
B29: Recommendation | C29: Treat as strategic optionality rather than a core growth pillar. If the board wants this to be a bigger part of the story, it likely requires a dedicated go-to-market decision (licensing strategy, partner identification) well before Year 10 — the current model does not assume any early groundwork toward this segment.
B31: 5. Ukraine — Landmine/UXO Clearance (Incremental)
B32: The single largest identifiable near-term demand shock in this market
B33: Total programme size | C33: Current best estimate for full clearance of Ukraine is $29-31 billion (Ukraine Ministry of Economy RDNA4 assessment, Feb 2025: $29.8bn; most recent 2026 estimate: $31bn, down from an earlier World Bank estimate of $36-37bn due to improved technology and methodology). This is a ONE-TIME total capital need to clear ~139,000 km² of contaminated territory, not an annual figure.
B34: Annual economic cost of NOT clearing | C34: Ukraine's economy is estimated to lose $11 billion per year due to unexploded ordnance and mines — separate from the cost of clearing them, but useful context for why donor and Ukrainian government urgency is high despite funding constraints.
B35: Realistic annual disbursement | C35: Actual current government demining budget for 2026 is UAH 2 billion (~$45 million) — illustrating the huge gap between total need ($29-31bn) and current funding pace. This model uses $2.0bn/year as a MODELED estimate of realistic annual disbursement across all donors/programs (not just the Ukrainian government line), reflecting the scale-up expected as reconstruction financing (EU, World Bank, bilateral) comes online post-conflict, but still far below the theoretical 3-4 year full-clearance pace the $29-31bn total would imply if funded at speed.
B36: Contracting model | C36: Ukraine's Ministry of Economy runs a competitive tender process for demining contracts — operators bid, average cost is ~UAH 60,000/hectare (~$1,360), with prices up ~30% over two years as easier sites are exhausted and remaining contamination (trenches, cluster munitions, combined minefields) becomes harder. This is a genuinely commercial, contestable market — a strong entry point for TWB specifically because it is open to competitive international operators, unlike some domestic-only defense procurement.
B38: All figures on this tab flow into the TAM-SAM-SOM and Revenue Build tabs. Full citations: Sources tab.

Sheet Revenue Build
B2: 10-15 Year Revenue Forecast
B3: All figures $M unless noted. Year 0 = FY2026 (current state, <$5M revenue). Yellow = assumption.
B6: Calendar year | D6: 2026 | E6: 2027 | F6: 2028 | G6: 2029 | H6: 2030 | I6: 2031 | J6: 2032 | K6: 2033 | L6: 2034 | M6: 2035 | N6: 2036 | O6: 2037 | P6: 2038 | Q6: 2039 | R6: 2040 | S6: 2041
B7: Model year | D7: Y0 | E7: Y1 | F7: Y2 | G7: Y3 | H7: Y4 | I7: Y5 | J7: Y6 | K7: Y7 | L7: Y8 | M7: Y9 | N7: Y10 | O7: Y11 | P7: Y12 | Q7: Y13 | R7: Y14 | S7: Y15
B9: PHASE GATES — geographic & segment entry timing (modeled)
B10: Canada domestic (RCMP, police, provincial/federal) — existing base | D10: 1 | E10: 1 | F10: 1 | G10: 1 | H10: 1 | I10: 1 | J10: 1 | K10: 1 | L10: 1 | M10: 1 | N10: 1 | O10: 1 | P10: 1 | Q10: 1 | R10: 1 | S10: 1
B11: US market entry (EOD services, law enforcement) | D11: 0 | E11: 1 | F11: 1 | G11: 1 | H11: 1 | I11: 1 | J11: 1 | K11: 1 | L11: 1 | M11: 1 | N11: 1 | O11: 1 | P11: 1 | Q11: 1 | R11: 1 | S11: 1
B12: Europe/NATO expansion (EOD services + ammo demil) | D12: 0 | E12: 0 | F12: 1 | G12: 1 | H12: 1 | I12: 1 | J12: 1 | K12: 1 | L12: 1 | M12: 1 | N12: 1 | O12: 1 | P12: 1 | Q12: 1 | R12: 1 | S12: 1
B13: Ukraine market entry (competitive demining tenders) | D13: 0 | E13: 0 | F13: 0 | G13: 1 | H13: 1 | I13: 1 | J13: 1 | K13: 1 | L13: 1 | M13: 1 | N13: 1 | O13: 1 | P13: 1 | Q13: 1 | R13: 1 | S13: 1
B14: Middle East expansion (military ordnance destruction) | D14: 0 | E14: 0 | F14: 0 | G14: 0 | H14: 0 | I14: 0 | J14: 0 | K14: 1 | L14: 1 | M14: 1 | N14: 1 | O14: 1 | P14: 1 | Q14: 1 | R14: 1 | S14: 1
B15: Chemical weapons demil (specialist entry, later-phase) | D15: 0 | E15: 0 | F15: 0 | G15: 0 | H15: 0 | I15: 0 | J15: 0 | K15: 0 | L15: 0 | M15: 1 | N15: 1 | O15: 1 | P15: 1 | Q15: 1 | R15: 1 | S15: 1
B16: Metals recovery / restocking line — full commercial rollout | D16: 0 | E16: 1 | F16: 1 | G16: 1 | H16: 1 | I16: 1 | J16: 1 | K16: 1 | L16: 1 | M16: 1 | N16: 1 | O16: 1 | P16: 1 | Q16: 1 | R16: 1 | S16: 1
B18: CAPABILITY ROADMAP — what comes online each year, and why (plain-language view of the phase gates above)
B19: This table restates the phase gates above as a narrative: what capability, license, or market access TWB needs to add each year, and the prerequisite that gates it. All entries are MODELED planning assumptions.
B20: Year | C20: Milestone | D20: Prerequisite / dependency
B21: Y0-1 | C21: Consolidate Canadian base: deepen existing RCMP/police/provincial and federal small-arms and ammunition destruction contracts (building on TWB's established eMACS/MACS platform, in use with the RCMP since 2001); stand up metals recovery as a commercial line (not just disposal) on the existing Canadian book.
C22: → No new licensing required — this is operational maturity on the existing business. Metals recovery requires negotiating recovery-rights language into existing/renewed Canadian contracts and securing smelter/refiner offtake relationships.
B23: Y1 | C23: US market entry: EOD services and law-enforcement destruction contracts, leveraging the existing eMACS/MACS product already built to meet or exceed California EPA emissions standards.
C24: → The most natural first international expansion for a Canadian operator — no ITAR foreign-ownership barrier applies the way it would for a non-North-American entrant, and TWB's equipment is already positioned against California EPA standards, ahead of most US state environmental requirements. Still requires US state-level environmental/destruction licensing and law-enforcement agency relationship-building, but this is a permitting and sales-cycle problem, not a structural market-access barrier — the single biggest strategic advantage of TWB's Canadian base versus a UK or EU competitor eyeing the US.
B25: Y2 | C25: Europe/NATO market entry: first framework-level EOD services and ammunition demil contracts.
C26: → Requires EU/NATO-recognized certifications and licensing distinct from the Canada/US regulatory base, plus a reference-able North American track record (Canada + early US wins) to bid credibly — sequenced after US entry since Europe requires a genuinely new certification base rather than leveraging existing standards compliance.
B27: Y3 | C27: Ukraine market entry: qualify as an international operator in Ukraine's competitive demining tender process.
C28: → Requires Ukrainian government accreditation/registration as a demining operator, in-country operational capability (personnel, equipment, insurance for a live conflict/post-conflict zone), and is realistically sequenced after Europe entry so TWB is bidding with an established international track record, not as a first-time international entrant.
B29: Y7 | C29: Middle East expansion: military ordnance destruction contracts.
C30: → Requires government-to-government relationship building and country-specific licensing; sequenced last among the core geographies given the added complexity, and only pursued once TWB has demonstrated delivery at scale in at least two other regions.
B31: Y10 | C31: Chemical weapons demilitarization: enter as a specialist, licensed contributor to a small number of remaining government-run CW demil programs.
C32: → Requires OPCW-compliant licensing and government sponsorship — realistically only achievable via partnership/JV with an already-certified operator, or acquisition of one. This is optionality, not a core growth pillar (see Segment Detail tab) — the board should treat this as something to scope in Year 7-8 if it is to be ready by Year 10, not something that happens by default.
B34: REVENUE BY SEGMENT ($M)
B35: Canada domestic — RCMP, police & provincial/federal destruction (existing line) | D35: 3.5 | E35: =D35*1.14 -> 3.99 | F35: =E35*1.14 -> 4.5486 | G35: =F35*1.14 -> 5.185404 | H35: =G35*1.14 -> 5.9113606 | I35: =H35*1.14 -> 6.738951 | J35: =I35*1.14 -> 7.6824042 | K35: =J35*1.14 -> 8.7579408 | L35: =K35*1.14 -> 9.9840525 | ... S35: =R35*1.14 -> 24.982783
B36: US — EOD services & law enforcement destruction contracts | D36: 0 | E36: =IF(E11=1,1.5,0) -> 1.5 | F36: =IF(F11=1,5,0) -> 5 | G36: =IF(G11=1,12.5,0) -> 12.5 | H36: =IF(H11=1,23,0) -> 23 | I36: =IF(I11=1,H36*1.2,0) -> 27.6 | J36: =IF(J11=1,I36*1.2,0) -> 33.12 | K36: =IF(K11=1,J36*1.2,0) -> 39.744 | L36: =IF(L11=1,K36*1.2,0) -> 47.6928 | M36: =IF(M11=1,L36*1.2,0) -> 57.23136 | N36: =IF(N11=1,M36*1.2,0) -> 68.677632 | O36: =IF(O11=1,N36*1.2,0) -> 82.413158 | P36: =IF(P11=1,O36*1.2,0) -> 98.89579 | ... S36: =IF(S11=1,R36*1.2,0) -> 170.89193
B37: Europe/NATO — EOD services & ammunition demil contracts | D37: 0 | E37: 0 | F37: =IF(F12=1,1.5,0) -> 1.5 | G37: =IF(G12=1,5.5,0) -> 5.5 | H37: =IF(H12=1,14,0) -> 14 | I37: =IF(I12=1,H37*1.26,0) -> 17.64 | J37: =IF(J12=1,I37*1.26,0) -> 22.2264 | K37: =IF(K12=1,J37*1.26,0) -> 28.005264 | L37: =IF(L12=1,K37*1.26,0) -> 35.286633 | M37: =IF(M12=1,L37*1.26,0) -> 44.461157 | N37: =IF(N12=1,M37*1.26,0) -> 56.021058 | O37: =IF(O12=1,N37*1.26,0) -> 70.586533 | P37: =IF(P12=1,O37*1.26,0) -> 88.939032 | ... S37: =IF(S12=1,R37*1.26,0) -> 177.9115
B38: Ukraine — competitive demining & UXO clearance tenders | D38: =IF(D13=1,0,0) -> 0 | E38: =IF(E13=1,0,0) -> 0 | F38: =IF(F13=1,0,0) -> 0 | G38: =IF(G13=1,3,0) -> 3 | H38: =IF(H13=1,11,0) -> 11 | I38: =IF(I13=1,27,0) -> 27 | J38: =IF(J13=1,48,0) -> 48 | K38: =IF(K13=1,J38*1.115,0) -> 53.52 | L38: =IF(L13=1,K38*1.115,0) -> 59.6748 | M38: =IF(M13=1,L38*1.115,0) -> 66.537402 | N38: =IF(N13=1,M38*1.115,0) -> 74.189203 | O38: =IF(O13=1,N38*1.115,0) -> 82.720962 | P38: =IF(P13=1,O38*1.115,0) -> 92.233872 | Q38: =IF(Q13=1,P38*1.115,0) -> 102.84077 | R38: =IF(R13=1,Q38*1.115,0) -> 114.66746 | S38: =IF(S13=1,R38*1.115,0) -> 127.85421
B39: Middle East — military ordnance destruction contracts | D39: =IF(D14=1,0,0) -> 0 | E39: =IF(E14=1,0,0) -> 0 | F39: =IF(F14=1,0,0) -> 0 | G39: =IF(G14=1,0,0) -> 0 | H39: =IF(H14=1,0,0) -> 0 | I39: =IF(I14=1,0,0) -> 0 | J39: =IF(J14=1,0,0) -> 0 | K39: =IF(K14=1,1,0) -> 1 | L39: =IF(L14=1,3.5,0) -> 3.5 | M39: =IF(M14=1,8.5,0) -> 8.5 | N39: =IF(N14=1,16,0) -> 16 | O39: =IF(O14=1,N39*1.16,0) -> 18.56 | P39: =IF(P14=1,O39*1.16,0) -> 21.5296 | Q39: =IF(Q14=1,P39*1.16,0) -> 24.974336 | R39: =IF(R14=1,Q39*1.16,0) -> 28.97023 | S39: =IF(S14=1,R39*1.16,0) -> 33.605467
B40: Chemical weapons demil — specialist government-to-government contracts | D40: =IF(D15=1,0,0) -> 0 | E40: =IF(E15=1,0,0) -> 0 | F40: =IF(F15=1,0,0) -> 0 | G40: =IF(G15=1,0,0) -> 0 | H40: =IF(H15=1,0,0) -> 0 | I40: =IF(I15=1,0,0) -> 0 | J40: =IF(J15=1,0,0) -> 0 | K40: =IF(K15=1,0,0) -> 0 | L40: =IF(L15=1,0,0) -> 0 | M40: =IF(M15=1,0.8,0) -> 0.8 | N40: =IF(N15=1,2.5,0) -> 2.5 | O40: =IF(O15=1,5,0) -> 5 | P40: =IF(P15=1,O40*1.1,0) -> 5.5 | Q40: =IF(Q15=1,P40*1.1,0) -> 6.05 | R40: =IF(R15=1,Q40*1.1,0) -> 6.655 | S40: =IF(S15=1,R40*1.1,0) -> 7.3205
B42: Subtotal — phased-entry destruction/EOD/demining services revenue | D42: =SUM(D35:D40) -> 3.5 | E42: =SUM(E35:E40) -> 5.49 | F42: =SUM(F35:F40) -> 11.0486 | G42: =SUM(G35:G40) -> 26.185404 | H42: =SUM(H35:H40) -> 53.911361 | I42: =SUM(I35:I40) -> 78.978951 | J42: =SUM(J35:J40) -> 111.0288 | K42: =SUM(K35:K40) -> 131.0272 | ... S42: =SUM(S35:S40) -> 542.56639
B44: ACQUISITION PROGRAM ($M) — investment/M&A assumptions feeding into total revenue below
B45: The phased contract-win build above, on its own, reaches roughly $510-515M by Year 15 — well short of the $1.09bn needed for 10% share of the grown Year-15 SAM. Reaching the 10% target requires an explicit, funded acquisition program as well, not just contract wins. This section models that program's inputs — deal count, size, timing, post-acquisition growth — which then feed directly into the single TOTAL TWB REVENUE line below (acquired revenue is not tracked as a separate reported stream past this point; it is simply part of total revenue and total growth from the year each deal closes onward). All figures here are MODELED planning assumptions, not commitments to specific targets.
B46: Acquisition assumption | C46: Value
B47: Number of acquisitions over 15 years | C47: 7
B48: Average acquired revenue at entry ($M, modeled) | C48: 18
...

Sheet Metals Recovery
B2: Metals Recovery / Domestic Restocking Revenue Logic
B3: The 'turning post-mission issues into metals to support restocking of domestic metals units' revenue line
B6: SOURCED — current scrap metal reference prices (Aug 2026)
B7: Metal | C7: Price range | D7: Basis | E7: Note
B8: Brass (shell casings — clean yellow brass) | C8: $1.90 - $3.70 / lb | D8: SOURCED | E8: Wide range across trackers/regions; follows copper+zinc prices. $3.30-3.70/lb quoted mid-2026 by one tracker; $1.90-2.10/lb by another (Aug 2026) — regional/grade variance is real.
B9: Steel (ferrous — cases, large-format components) | C9: $100 - $165 / gross ton | D9: SOURCED | E9: Low $/lb but highest tonnage; no single global benchmark, set by regional mill buying programs.
B10: Copper (where present — wiring, some components) | C10: $2.40 - $6.60 / lb | D10: SOURCED | E10: COMEX benchmark ~$6.60/lb (Aug 2026); scrap yards pay a discount to benchmark, typically netting $2.40-3.70/lb for mixed/dirty grades.
B11: Aluminum (where present) | C11: $0.55 - $0.82 / lb | D11: SOURCED | E11: Lower-value stream, present in some ordnance/equipment casings.
B13: MODELED — revenue conversion logic
B14: Metals recovery is modeled as a REVENUE SHARE MULTIPLIER on top of destruction/demil services revenue, not sized independently bottom-up (tonnage-level throughput data isn't available at this stage of planning). This should be replaced with a bottom-up tonnage x price model once TWB has real throughput data from its own operations.
B16: Assumption: recovered metals revenue as % of underlying destruction services revenue | C16: 0.14
B18: Why this matters strategically (not just financially):
B19: • Metals recovery converts a cost center (secure disposal) into a revenue center — most competitors in pure EOD/demining treat destroyed material as waste with a disposal COST, not a recovery REVENUE.
B20: • It creates a genuine domestic supply-chain narrative — 'post-mission material becomes feedstock for domestic metals units' is a strong sovereignty/resilience pitch to government and defense buyers (Canadian, US, and European alike), particularly relevant given current North American and European focus on supply chain security for defense manufacturing inputs.
B21: • It's a natural moat: competitors without smelting/refining relationships or recovery-rights contract language can't easily replicate this margin, even if they can replicate the destruction service itself.
B23: Recommendation before finalizing for investor materials:
B24: Replace the 14% revenue-share placeholder with a bottom-up model once TWB has: (1) actual tonnage-per-contract data from current operations, (2) confirmed contract language on material recovery rights (many government destruction contracts specify the disposal method AND ownership of recovered material — this varies a lot by customer and jurisdiction), and (3) confirmed smelter/refiner offtake pricing (which will be below the retail scrap prices shown above).

Sheet Headcount & Ops
B2: Headcount Forecast
B3: FTE by function, implied by the Revenue Build tab. All MODELED (revenue-per-FTE benchmarks).
B6: Calendar year | D6: 2026 | E6: 2027 | F6: 2028 | G6: 2029 | H6: 2030 | I6: 2031 | J6: 2032 | K6: 2033 | L6: 2034 | M6: 2035 | N6: 2036 | O6: 2037 | P6: 2038 | Q6: 2039 | R6: 2040 | S6: 2041
B8: Revenue-per-FTE benchmarks (modeled, by function)
B9: These are planning assumptions, not sourced benchmarks for this specific niche industry (no clean public data exists for revenue/FTE in secure destruction specifically) — cross-checked loosely against defense services and environmental/industrial services comparables, which typically run $150-300k revenue/FTE for field-operations-heavy businesses.
B11: Function | C11: Rev/FTE ($k, modeled)
B12: Field operations — EOD/demining technicians & teams | C12: 180
B13: Metals recovery / processing operations | C13: 260
B14: Business development, contracts & tendering | C14: 500
B15: Program/project management | C15: 350
B16: QHSE, compliance, licensing/export control | C16: 400
B17: Corporate — finance, HR, leadership, admin | C17: 450
B19: FTE mix by function (% of total headcount, modeled — shifts toward field ops as scale grows)
B20: Field operations | D20: 0.35 | E20: 0.38 | F20: 0.42 | G20: 0.45 | H20: 0.48 | I20: 0.5 | J20: 0.52 | K20: 0.54 | L20: 0.55 | M20: 0.56 | N20: 0.57 | O20: 0.58 | P20: 0.58 | Q20: 0.59 | R20: 0.59 | S20: 0.6
B21: Metals recovery / processing | D21: 0.05 | E21: 0.08 | F21: 0.1 | G21: 0.11 | H21: 0.12 | I21: 0.13 | J21: 0.13 | K21: 0.14 | L21: 0.14 | M21: 0.14 | N21: 0.14 | O21: 0.14 | P21: 0.14 | Q21: 0.14 | R21: 0.14 | S21: 0.14
B22: BD, contracts & tendering | D22: 0.15 | E22: 0.14 | F22: 0.13 | G22: 0.12 | H22: 0.11 | I22: 0.1 | J22: 0.09 | K22: 0.08 | L22: 0.08 | M22: 0.07 | N22: 0.07 | O22: 0.07 | P22: 0.07 | Q22: 0.06 | R22: 0.06 | S22: 0.06
B23: Program/project management | D23: 0.15 | E23: 0.14 | F23: 0.13 | G23: 0.13 | H23: 0.12 | I23: 0.11 | J23: 0.11 | K23: 0.1 | L23: 0.1 | M23: 0.1 | N23: 0.09 | O23: 0.09 | P23: 0.09 | Q23: 0.09 | R23: 0.09 | S23: 0.08
B24: QHSE, compliance, licensing/export control | D24: 0.1 | E24: 0.1 | F24: 0.1 | G24: 0.09 | H24: 0.09 | I24: 0.08 | J24: 0.08 | K24: 0.08 | L24: 0.07 | M24: 0.07 | N24: 0.07 | O24: 0.06 | P24: 0.06 | Q24: 0.06 | R24: 0.06 | S24: 0.06
B25: Corporate | D25: 0.2 | E25: 0.16 | F25: 0.12 | G25: 0.1 | H25: 0.08 | I25: 0.08 | J25: 0.07 | K25: 0.06 | L25: 0.06 | M25: 0.06 | N25: 0.06 | O25: 0.06 | P25: 0.06 | Q25: 0.06 | R25: 0.06 | S25: 0.06
B27: Blended revenue/FTE ($k) — applies to ORGANIC + metals revenue only (see note below on acquired headcount) | D27: =D20*C12+D21*C13+D22*C14+D23*C15+D24*C16+D25*C17 -> 333.5 | E27: =E20*C12+E21*C13+E22*C14+E23*C15+E24*C16+E25*C17 -> 320.2 | F27: =F20*C12+F21*C13+F22*C14+F23*C15+F24*C16+F25*C17 -> 306.1 | G27: =G20*C12+G21*C13+G22*C14+G23*C15+G24*C16+G25*C17 -> 296.1 | H27: =H20*C12+H21*C13+H22*C14+H23*C15+H24*C16+H25*C17 -> 286.6 | I27: =I20*C12+I21*C13+I22*C14+I23*C15+I24*C16+I25*C17 -> 280.3 | J27: =J20*C12+J21*C13+J22*C14+J23*C15+J24*C16+J25*C17 -> 274.4 | K27: =K20*C12+K21*C13+K22*C14+K23*C15+K24*C16+K25*C17 -> 267.6 | L27: =L20*C12+L21*C13+L22*C14+L23*C15+L24*C16+L25*C17 -> 265.4 | M27: =M20*C12+M21*C13+M22*C14+M23*C15+M24*C16+M25*C17 -> 262.2 | N27: =N20*C12+N21*C13+N22*C14+N23*C15+N24*C16+N25*C17 -> 260.5 | O27: =O20*C12+O21*C13+O22*C14+O23*C15+O24*C16+O25*C17 -> 258.3 | P27: =P20*C12+P21*C13+P22*C14+P23*C15+P24*C16+P25*C17 -> 258.3 | Q27: =Q20*C12+Q21*C13+Q22*C14+Q23*C15+Q24*C16+Q25*C17 -> 255.1 | R27: =R20*C12+R21*C13+R22*C14+R23*C15+R24*C16+R25*C17 -> 255.1 | S27: =S20*C12+S21*C13+S22*C14+S23*C15+S24*C16+S25*C17 -> 253.4
B29: Acquired-company revenue/FTE ($k, modeled — typically LOWER than TWB's blended organic ratio) | C29: 140
B31: IMPLIED HEADCOUNT
B32: Blended revenue/FTE for the year, weighted by the acquisition program's share of total revenue | D32: =IFERROR((1-('Revenue Build'!D54/'Revenue Build'!D62))*D27+('Revenue Build'!D54/'Revenue Build'!D62)*$C$29,D27) -> 333.5 | E32: =IFERROR((1-('Revenue Build'!E54/'Revenue Build'!E62))*E27+('Revenue Build'!E54/'Revenue Build'!E62)*$C$29,E27) -> 320.2 | F32: =IFERROR((1-('Revenue Build'!F54/'Revenue Build'!F62))*F27+('Revenue Build'!F54/'Revenue Build'!F62)*$C$29,F27) -> 208.37944 | G32: =IFERROR((1-('Revenue Build'!G54/'Revenue Build'!G62))*G27+('Revenue Build'!G54/'Revenue Build'!G62)*$C$29,G27) -> 207.97527 | H32: =IFERROR((1-('Revenue Build'!H54/'Revenue Build'!H62))*H27+('Revenue Build'!H54/'Revenue Build'!H62)*$C$29,H27) -> 212.68147 | I32: =IFERROR((1-('Revenue Build'!I54/'Revenue Build'!I62))*I27+('Revenue Build'!I54/'Revenue Build'!I62)*$C$29,I27) -> 218.01572 | J32: =IFERROR((1-('Revenue Build'!J54/'Revenue Build'!J62))*J27+('Revenue Build'!J54/'Revenue Build'!J62)*$C$29,J27) -> 214.86231 | K32: =IFERROR((1-('Revenue Build'!K54/'Revenue Build'!K62))*K27+('Revenue Build'!K54/'Revenue Build'!K62)*$C$29,K27) -> 211.88739 | ... S32: =IFERROR((1-('Revenue Build'!S54/'Revenue Build'!S62))*S27+('Revenue Build'!S54/'Revenue Build'!S62)*$C$29,S27) -> 204.69924
B33: Total FTE | D33: ='Revenue Build'!D62*1000/D32 -> 10.494753 | E33: ='Revenue Build'!E62*1000/E32 -> 19.545909 | F33: ='Revenue Build'!F62*1000/F32 -> 146.82544 | G33: ='Revenue Build'!G62*1000/G32 -> 329.61303 | H33: ='Revenue Build'!H62*1000/H32 -> 582.86202 | I33: ='Revenue Build'!I62*1000/I32 -> 742.68387 | J33: ='Revenue Build'!J62*1000/J32 -> 1057.5875 | K33: ='Revenue Build'!K62*1000/K32 -> 1251.2935 | ... S33: ='Revenue Build'!S62*1000/S32 -> 5296.0907
B35: Headcount by function (FTE)
B36: Field operations | D36: =D33*D20 -> 3.6731634 | E36: =E33*E20 -> 7.4274453 | F36: =F33*F20 -> 61.666687 | G36: =G33*G20 -> 148.32587 | H36: =H33*H20 -> 279.77377 | I36: =I33*I20 -> 371.34193 | J36: =J33*J20 -> 549.94552 | K36: =K33*K20 -> 675.69847 | ... S36: =S33*S20 -> 3177.6544
B37: Metals recovery / processing | D37: =D33*D21 -> 0.52473763 | E37: =E33*E21 -> 1.5636727 | F37: =F33*F21 -> 14.682544 | G37: =G33*G21 -> 36.257434 | H37: =H33*H21 -> 69.943442 | I37: =I33*I21 -> 96.548903 | J37: =J33*J21 -> 137.48638 | K37: =K33*K21 -> 175.18108 | ... S37: =S33*S21 -> 741.4527
B38: BD, contracts & tendering | D38: =D33*D22 -> 1.5742129 | E38: =E33*E22 -> 2.7364272 | F38: =F33*F22 -> 19.087308 | G38: =G33*G22 -> 39.553564 | H38: =H33*H22 -> 64.114822 | I38: =I33*I22 -> 74.268387 | J38: =J33*J22 -> 95.182878 | K38: =K33*K22 -> 100.10348 | ... S38: =S33*S22 -> 317.76544
B39: Program/project management | D39: =D33*D23 -> 1.5742129 | E39: =E33*E23 -> 2.7364272 | F39: =F33*F23 -> 19.087308 | G39: =G33*G23 -> 42.849695 | H39: =H33*H23 -> 69.943442 | I39: =I33*I23 -> 81.695225 | J39: =J33*J23 -> 116.33463 | K39: =K33*K23 -> 125.12935 | ... S39: =S33*S23 -> 423.68725
B40: QHSE, compliance, licensing/export control | D40: =D33*D24 -> 1.0494753 | E40: =E33*E24 -> 1.9545909 | F40: =F33*F24 -> 14.682544 | G40: =G33*G24 -> 29.665173 | H40: =H33*H24 -> 52.457582 | I40: =I33*I24 -> 59.414709 | J40: =J33*J24 -> 84.607002 | K40: =K33*K24 -> 100.10348 | ... S40: =S33*S24 -> 317.76544
B41: Corporate | D41: =D33*D25 -> 2.0989505 | E41: =E33*E25 -> 3.1273454 | F41: =F33*F25 -> 17.619053 | G41: =G33*G25 -> 32.961303 | H41: =H33*H25 -> 46.628961 | I41: =I33*I25 -> 59.414709 | J41: =J33*J25 -> 74.031127 | K41: =K33*K25 -> 75.077608 | ... S41: =S33*S25 -> 317.76544
B43: Sanity check — Year 15 total FTE and revenue/FTE:
B44: Year 15 TOTAL FTE: | C44: =S33 -> 5296.0907
B45: Year 15 revenue ($M): | C45: ='Revenue Build'!S62 -> 1084.1057
B46: Implied blended revenue/FTE across whole business ($k): | C46: ='Revenue Build'!S62*1000/S33 -> 204.69924
B47: NOTE: this headcount total blends organically-grown and acquisition-transferred staff into a single figure. Acquired businesses bring their own existing employees at close, so the growth in headcount is not the same as TWB organic hiring — the blended revenue/FTE ratio above is intentionally weighted down each year in proportion to how much of that year's revenue comes from the acquisition program, to keep the total honest even though it isn't broken out as a separate line. See the Acquisition Program section on the Revenue Build tab for the underlying deal assumptions driving this.

Sheet Scenarios
B2: Scenario Summary — Base / Upside / Downside
B3: Manually computed scenario table (adjust the Revenue Build tab assumptions and re-read these outputs for a live re-run)
B6: This tab summarizes three scenarios built by flexing the key MODELED levers. To actually re-run a scenario, adjust the yellow cells on Revenue Build, TAM-SAM-SOM, and Metals Recovery tabs directly, then update this table's Year-15 outputs by hand or by re-pointing the formulas below to a duplicated Revenue Build tab per scenario.
B8: Key levers and their scenario settings
B9: Lever | C9: Downside | D9: Base (this model) | E9: Upside
B10: Year-15 share of GROWN SAM (target) | C10: 5% | D10: 10% (~$1.08bn — see Revenue Build tab) | E10: 16%
B11: Number of acquisitions over 15 years | C11: 3 (deal pipeline dries up / capital constrained) | D11: 7 | E11: 11 (faster-than-planned consolidation)
B12: Average acquired revenue at entry | C12: $10M (smaller bolt-ons only) | D12: $18M | E12: $28M (larger platform deals available)
B13: Post-acquisition growth rate | C13: 6% (integration drags, target underperforms) | D13: 15% | E13: 20% (strong integration, cross-sell wins)
B14: Acquisition timing | C14: Back-loaded — first deal not until Year 5 | D14: Front-loaded — 3 of 7 deals in Years 2-4 | E14: Even earlier — first deal Year 1
B15: Europe/NATO organic mature-year growth rate | C15: 10% | D15: 26% | E15: 34%
B16: Ukraine market entry timing | C16: Year 5 (delayed — funding crisis persists) | D16: Year 3 | E16: Year 2 (accelerated reconstruction financing)
B17: US market entry timing | C17: Year 3 (state licensing/relationship-building takes longer than expected) | D17: Year 1 | E17: Year 1, faster ramp (existing California EPA-aligned eMACS platform accelerates state approvals)
B18: Metals recovery revenue share (organic) | C18: 6% (recovery rights rarely granted) | D18: 14% | E18: 22%
B20: Approximate Year-15 outcomes (directional — see note above on how to re-run precisely)
B21: Metric | C21: Downside | D21: Base | E21: Upside
B22: Year-15 TOTAL revenue ($M) | C22: 450-550 (~4-5% SAM share) | D22: ~1,083 (~10% SAM share — see Revenue Build tab) | E22: 2,100-2,700 (~19-25% SAM share)
B23: Year-15 TOTAL FTE | C23: 1,300-2,000 | D23: ~5,300 (see Headcount & Ops tab) | E23: 9,500-13,000
B24: Primary risk driver | C24: M&A pipeline fails to materialize at pace/size; acquired businesses underperform post-close; contract wins in Europe/Ukraine also disappoint | D24: Deal pipeline executes roughly to plan; contract-win base holds | E24: TWB becomes a recognized consolidator, target companies come to TWB, integration playbook compounds with each deal
B26: Read for the board:
B27: This plan blends contract-win growth with an explicit, funded acquisition program — hitting the 10%-of-grown-SAM target ($1.08bn) requires both. Contract wins across Canada/US/Europe/Ukraine/Middle East/chem-weapons reach a real, substantial base on their own, but only get roughly halfway to the target; the acquisition program (seven modeled deals, most of them in the first half of the plan) closes the remainder. Two consequences worth sitting with: (1) capital requirements are front-loaded — the board needs to be ready to fund and execute 3+ acquisitions in Years 2-4 alone, well before the contract-win business has fully proven itself at scale, and (2) a large share of Year-15 headcount arrives via acquisition rather than organic hiring — see the Headcount & Ops tab for how the blended revenue/FTE ratio accounts for this without breaking it into a separate reported line.
B28: On market growth: the market itself grows over 15 years too (Ukraine reconstruction ramp, European rearmament, ammunition stockpile turnover, partly offset by a shrinking chemical weapons segment) — Year-15 SAM is modeled at ~$10.9bn, roughly double today's $5.2bn. The 10% target is measured against that grown figure, which is why it requires ~$1.08bn rather than the ~$523M a static-2026-market version of this model would have implied.
B29: The single most important number on this whole tab is the acquisition timing assumption (Revenue Build tab): deals made early compound for many years at the post-acquisition growth rate; deals made late barely contribute. If real-world M&A execution runs even one to two years behind the modeled pace, the Year-15 total falls well short of 10% share even if the eventual deal count and average size are hit — pace matters as much as volume.

Sheet Sources
B2: Sources
B3: Every SOURCED figure used in this model, with citation and access date
B6: Figure used | C6: Source | D6: Date
B7: TWB Designs Inc — Canadian company (Ancaster, Ontario), eMACS/MACS ammunition destruction system | C7: twbdesigns.com | D7: Aug 2026
B8: eMACS/MACS co-developed with RCMP, in use since 2001; RCMP, various police forces and munitions plants as customers | C8: officer.com product listing; cadsammunitiondisposal.com | D8: 2011 / Aug 2026
B9: eMACS built to meet or exceed California EPA, NATO and EU emissions standards | C9: rocketreach.co company profile citing twbdesigns.com | D9: Aug 2026
B10: Global mine action funding: $1.07bn (2024) | C10: Landmine Monitor 2025, the-monitor.org/online-reader/landmine-monitor-2025 | D10: Feb 2026
B11: International vs national mine action funding split | C11: Landmine Monitor 2025 | D11: Feb 2026
B12: Top mine action donors (US, Germany, EU) | C12: Landmine Monitor 2025 | D12: Feb 2026
B13: US foreign assistance freeze Q1 2025 impact on mine action | C13: ICBL-CMC, Landmine Monitor 2025 summary, icblcmc.org | D13: Feb 2026
B14: EOD equipment+services market: $8.55bn (2025) | C14: Global Growth Insights, globalgrowthinsights.com/market-reports/explosive-ordnance-disposal-eod-market-109006 | D14: Feb 2026
B15: EOD equipment+services market: $9.6bn (2025) | C15: Spherical Insights, sphericalinsights.com | D15: Apr 2026
B16: EOD equipment-only market: $6.24-7.2bn (2025) | C16: The Business Research Company / DataIntelo market reports | D16: 2026
B17: EOD services-only market: $1.18bn (2025) | C17: Intel Market Research, intelmarketresearch.com | D17: Feb 2026
... B35: American Battery Technology Co. (NASDAQ: ABAT): ~$380-430M enterprise value, ~$9.45M TTM revenue, ~40.3x EV/Sales, negative EBITDA | C35: fullratio.com; tradingview.com; wallstreetzen.com | D35: Aug 2026
B36: Note on MODELED (unsourced) figures:
B37: Ammunition demilitarization market size ($2.5bn/yr), chemical weapons demil ($400M/yr), Ukraine realistic annual disbursement ($2.0bn/yr), all SAM adjustment factors, the Year-15 SAM share target (10%), the metals recovery revenue share (14%), and all revenue-per-FTE benchmarks are modeled/estimated by this exercise, not pulled from third-party published sources — no clean public market sizing exists for these specific figures. Each is flagged in yellow on its originating tab with the reasoning behind the estimate. Recommend validating the largest of these (ammunition demil market size, and Year-15 SAM share) with primary research or industry expert interviews before finalizing external investor materials.

Sheet 2027 Go-Public Valuation
B2: Illustrative 2027 Go-Public Valuation — Growth-Stage SPAC/IPO Methodology
B3: Standard growth-stage go-public valuation methodology (comp universe, EV/EBITDA multiples, discounted future value) applied to TWB's real starting financials and Year-10 operating model output.
B6: METHODOLOGY OVERVIEW (READ THIS FIRST)
B7: Growth-stage companies going public via SPAC merger, direct listing, or IPO in capital-intensive, government/industrial-facing sectors (metals recycling, critical minerals, specialty manufacturing, defense services) are typically valued using a small, standard set of methods: (1) build a comp universe of named public companies across relevant categories; (2) take the median EV/EBITDA multiple of that universe; (3) apply it to the company's own FUTURE (not current) EBITDA estimate to get a future firm value; (4) discount that future firm value back to today at a specified discount rate over the years remaining until that future point; (5) compare the result to an actual or illustrative deal price to show it as a discount (or premium) to computed fair value. This tab builds that exact bridge for TWB, using the 10-year point in the operating model as the projection horizon.
B8: CRITICAL CONTEXT: this entire class of valuation approach is built on PITCHED forward guidance and a FUTURE profitability estimate, not audited actuals. That is standard practice for growth-stage go-public deals in these sectors, but it is also exactly the mechanism that has produced some of the most dramatic valuation-to-outcome gaps in recent capital markets history — richly-priced, pre-revenue growth stories in adjacent sectors (metals/battery recycling, critical minerals) have in some cases gone on to miss their own near-term guidance by wide margins, post large losses, cut staff, and in at least one prominent case filed for bankruptcy protection within several years of a SPAC listing priced this way. This is not a hedge to skim past — it is the central lesson of using this framework at all: a valuation built on steep forward guidance and a discounted future estimate can produce an eye-catching headline number that has no necessary relationship to what the company is actually worth once real results arrive. Every number on this tab should be read as 'what a well-constructed comp-based pitch would say,' not as a prediction of TWB's actual value in 2036.
B10: SECTION 1 — TWB today: actual combined financials (SOURCED, compiled financial statements)
B11: Real combined financials for TWB Designs Inc. and Canadian Ammunition Disposal Services Inc. (CADS), the two entities behind the current business, per compiled (unaudited) financial statements. This is the true starting point — smaller than the modeled Year-0 base used in the 15-year Revenue Build tab, which is treated as an aspirational pro-forma growth case built on TOP OF this real base, not a replacement for it.
B12: ($CAD) | C12: 2023 | D12: 2024 | E12: 2025
B13: CADS revenue | C13: 901305 | D13: 847761 | E13: 720044
B14: TWB Designs revenue | C14: 64425 | D14: 863500 | E14: 142812
B15: Combined revenue | C15: 965730 | D15: 1711261 | E15: 862856
B16: Combined gross profit | C16: 759474 | D16: 760306 | E16: 569099
B17: Combined EBITDA | C17: 419000 | D17: 492000 | E17: 235000
B18: Combined net income | C18: 337094 | D18: 589471 | E18: 125174
B20: Balance sheet at Dec 31, 2025 ($CAD)
B21: Combined cash | C21: 199098
B22: Combined total assets | C22: 628018
B23: Combined total liabilities | C23: 47689
B24: Combined book value (equity) | C24: 580329
B26: Note: effectively debt-free (only interest-bearing debt was a $40K CEBA loan at CADS, repaid 2023). TWB Designs revenue is lumpy — it sells the eMACS/MACS burner system episodically ($64K, $864K, $143K across 2023-2025) rather than on a recurring basis, and 2024's result included a one-time $265,874 FX gain. CADS revenue has declined ~20% over three years (2023-2025), which the current owner attributes to reduced operating effort ahead of a planned retirement rather than a structural demand decline, evidenced by an existing backlog of ~20 police agencies awaiting pickup — but this is unverified pending diligence.
B28: SECTION 2 — Comp universe for TWB's sector
B29: TWB has no direct, liquid public comp set for small-arms/ammunition destruction specifically. This uses the closest genuine proxy rather than fabricating a broad multi-category universe that doesn't exist: public and private-market Aerospace & Defense (A&D) services multiples.
B30: TWB comp category | C30: Example companies | D30: EV/EBITDA (public) | E30: EV/EBITDA (private/strategic) | F30: Basis
B31: Aerospace & Defense Services | C31: Cadre Holdings, and the broader public A&D services cohort | D31: 11.4 | E31: 19 | F31: SOURCED
B33: Note: this comp set is deliberately narrow rather than broad — an honest reflection of TWB's sector having few, thinly-traded direct public comparables, rather than a manufactured wide universe that would imply false precision.
B35: SECTION 3 — Discounted Future Value bridge (10-year basis)
B36: Applies the comp-median EV/EBITDA multiple (Section 2) to TWB's Year-10 modeled EBITDA, then discounts that future firm value back to today over a 10-year horizon — matching the number of years actually being projected, rather than an arbitrarily shorter discount window.
C37: Value | D37: Basis
B38: TWB Year-10 revenue, from the operating model (Revenue Build tab) | C38: ='Revenue Build'!N62 -> 480.47899 | D38: MODELED (operating plan)
B39: Assumed EBITDA margin at Year-10 scale (modeled — maturing, integrated platform) | C39: 0.2
B40: Implied Year-10 EBITDA | C40: =C38*C39 -> 96.095797
B42: Applying the comp-median multiple range to Year-10 EBITDA
B43: Low end of comp multiple range (public A&D services) | C43: =D31 -> 11.4
B44: High end of comp multiple range (private/strategic A&D deals) | C44: =E31 -> 19
B45: Future firm value — low end | C45: =C40*C43 -> 1095.4921
B46: Future firm value — high end | C46: =C40*C44 -> 1825.8202
B48: Discounting back to today
B49: Number of periods to discount back | C49: 10
B50: Discount rate | C50: 0.2
B51: Implied discounted firm value — low end | C51: =C45/((1+C50)^C49) -> 176.92809
...
